ERROR 2022-11-22 16:49:06,747 assertbase.py _get_error_info 235 self._outcome is None, it's not reasonable
ERROR 2022-11-22 16:49:06,757 assertbase.py _teardown_collect 273 <bound method HomePageTest.test_01_home_page_path of <case.homepage_test.HomePageTest testMethod=test_01_home_page_path>>
Traceback (most recent call last):
  File "c:\users\admin\appdata\local\programs\python\python38\lib\site-packages\minium\miniprogram\wx_minium.py", line 576, in connect_dev_tool
    self._get_system_info()
  File "c:\users\admin\appdata\local\programs\python\python38\lib\site-packages\minium\miniprogram\wx_minium.py", line 423, in _get_system_info
    system_info = self.get_system_info()
  File "c:\users\admin\appdata\local\programs\python\python38\lib\site-packages\minium\miniprogram\base_driver\minium_log.py", line 131, in wrapper
    result = func(*args, **kwargs)
  File "c:\users\admin\appdata\local\programs\python\python38\lib\site-packages\minium\miniprogram\wx_minium.py", line 625, in get_system_info
    self.call_wx_method("getSystemInfoSync")
  File "c:\users\admin\appdata\local\programs\python\python38\lib\site-packages\minium\miniprogram\base_driver\minium_log.py", line 131, in wrapper
    result = func(*args, **kwargs)
  File "c:\users\admin\appdata\local\programs\python\python38\lib\site-packages\minium\miniprogram\base_driver\minium_object.py", line 78, in call_wx_method
    return self._call_wx_method(method=method, args=args, plugin_appid=plugin_appid)
  File "c:\users\admin\appdata\local\programs\python\python38\lib\site-packages\minium\miniprogram\base_driver\minium_object.py", line 304, in _call_wx_method
    return self.connection.send("App.callWxMethod", params)
  File "c:\users\admin\appdata\local\programs\python\python38\lib\site-packages\minium\miniprogram\base_driver\connection.py", line 203, in send
    return self._receive_response(cmd)
  File "c:\users\admin\appdata\local\programs\python\python38\lib\site-packages\minium\miniprogram\base_driver\connection.py", line 230, in _receive_response
    raise MiniTimeoutError(
minium.framework.exception.MiniTimeoutError: [call App.callWxMethod] receive from remote timeout, id: 2e83c4e5-5c62-4d83-a59f-331bf9034538

During handling of the above exception, another exception occurred:

Traceback (most recent call last):
  File "c:\users\admin\appdata\local\programs\python\python38\lib\site-packages\minium\miniprogram\wx_minium.py", line 530, in launch_dev_tool
    self.connect_dev_tool()
  File "c:\users\admin\appdata\local\programs\python\python38\lib\site-packages\minium\miniprogram\base_driver\minium_log.py", line 131, in wrapper
    result = func(*args, **kwargs)
  File "c:\users\admin\appdata\local\programs\python\python38\lib\site-packages\minium\miniprogram\wx_minium.py", line 589, in connect_dev_tool
    raise MiniConnectError(
minium.framework.exception.MiniConnectError: three times try to connect Dev tool has all fail ...

During handling of the above exception, another exception occurred:

Traceback (most recent call last):
  File "c:\users\admin\appdata\local\programs\python\python38\lib\site-packages\minium\framework\libs\unittest\suite.py", line 63, in _handleClassSetUp
    _miniClassSetUp()
  File "c:\users\admin\appdata\local\programs\python\python38\lib\site-packages\minium\framework\minitest.py", line 244, in _miniClassSetUp
    native, mini, miniprogram = init_miniprogram(cls.CONFIG)
  File "c:\users\admin\appdata\local\programs\python\python38\lib\site-packages\minium\framework\minitest.py", line 141, in init_miniprogram
    mini = get_minium(cfg)
  File "c:\users\admin\appdata\local\programs\python\python38\lib\site-packages\minium\framework\minitest.py", line 106, in get_minium
    g_minium = minium.miniprogram.get_minium_driver(conf=cfg, native=g_native)
  File "c:\users\admin\appdata\local\programs\python\python38\lib\site-packages\minium\miniprogram\__init__.py", line 28, in get_minium_driver
    return APP[application](conf, *args, **kwargs)
  File "c:\users\admin\appdata\local\programs\python\python38\lib\site-packages\minium\miniprogram\wx_minium.py", line 110, in __init__
    self.launch_weapp()
  File "c:\users\admin\appdata\local\programs\python\python38\lib\site-packages\minium\miniprogram\base_driver\minium_log.py", line 131, in wrapper
    result = func(*args, **kwargs)
  File "c:\users\admin\appdata\local\programs\python\python38\lib\site-packages\minium\miniprogram\wx_minium.py", line 440, in launch_weapp
    self.launch_dev_tool()
  File "c:\users\admin\appdata\local\programs\python\python38\lib\site-packages\minium\miniprogram\base_driver\minium_log.py", line 131, in wrapper
    result = func(*args, **kwargs)
  File "c:\users\admin\appdata\local\programs\python\python38\lib\site-packages\minium\miniprogram\wx_minium.py", line 551, in launch_dev_tool
    raise MiniLaunchError(err_msg)
minium.framework.exception.MiniLaunchError: Error: Port 9420 is in use (code 10)
